Exception: 2 in %s:%d
Stack trace:
#0 %s(%d): test()
#1 {main}