Fatal error: Uncaught Exception: ops 2 in %sbug53511.php:11
Stack trace:
#0 %sbug53511.php(17): test()
#1 {main}

Next Exception: ops 1 in %sbug53511.php:4
Stack trace:
#0 %sbug53511.php(12): Foo->__destruct()
#1 %sbug53511.php(17): test()
#2 {main}
  thrown in %sbug53511.php on line 4