Fatal error: Uncaught Exception in %s:%d
Stack trace:
#0 [internal function]: crash()
#1 %s(%d): iterator_to_array(Object(Generator))
#2 {main}
  thrown in %s on line %d